<?xml version="1.0" ?>
<sdf version="1.7">
    <!-- Agricultural Ground Robot Model -->
    <model name="agricultural_ground_robot">
        <static>false</static>
        
        <!-- Main body link -->
        <link name="base_link">
            <inertial>
                <mass>100.0</mass>
                <inertia>
                    <ixx>8.33</ixx>
                    <iyy>8.33</iyy>
                    <izz>13.33</izz>
                    <ixy>0.0</ixy>
                    <ixz>0.0</ixz>
                    <iyz>0.0</iyz>
                </inertia>
            </inertial>
            
            <collision name="base_collision">
                <geometry>
                    <box>
                        <size>1.2 0.9 0.6</size>
                    </box>
                </geometry>
                <surface>
                    <friction>
                        <ode>
                            <mu>0.8</mu>
                            <mu2>0.8</mu2>
                        </ode>
                    </friction>
                </surface>
            </collision>

            <visual name="base_visual">
                <geometry>
                    <box>
                        <size>1.2 0.9 0.6</size>
                    </box>
                </geometry>
                <material>
                    <ambient>0.5 0.5 0.5 1</ambient>
                    <diffuse>0.5 0.5 0.5 1</diffuse>
                    <specular>0.1 0.1 0.1 1</specular>
                </material>
            </visual>

            <!-- RGBD Camera Sensor -->
            <sensor name="front_camera" type="rgbd_camera">
                <update_rate>30</update_rate>
                <camera>
                    <horizontal_fov>1.047</horizontal_fov>
                    <image>
                        <width>1280</width>
                        <height>720</height>
                        <format>R8G8B8</format>
                    </image>
                    <clip>
                        <near>0.1</near>
                        <far>100</far>
                    </clip>
                    <noise>
                        <type>gaussian</type>
                        <mean>0.0</mean>
                        <stddev>0.02</stddev>
                    </noise>
                </camera>
                <pose>0.5 0.0 0.4 0 0 0</pose>
            </sensor>

            <!-- IMU Sensor -->
            <sensor name="robot_imu" type="imu">
                <update_rate>100</update_rate>
                <imu>
                    <angular_velocity>
                        <x>
                            <noise type="gaussian">
                                <mean>0.0</mean>
                                <stddev>0.007</stddev>
                                <bias_mean>0.001</bias_mean>
                            </noise>
                        </x>
                        <y>
                            <noise type="gaussian">
                                <mean>0.0</mean>
                                <stddev>0.007</stddev>
                                <bias_mean>0.001</bias_mean>
                            </noise>
                        </y>
                        <z>
                            <noise type="gaussian">
                                <mean>0.0</mean>
                                <stddev>0.007</stddev>
                                <bias_mean>0.001</bias_mean>
                            </noise>
                        </z>
                    </angular_velocity>
                    <linear_acceleration>
                        <x>
                            <noise type="gaussian">
                                <mean>0.0</mean>
                                <stddev>0.007</stddev>
                                <bias_mean>0.002</bias_mean>
                            </noise>
                        </x>
                        <y>
                            <noise type="gaussian">
                                <mean>0.0</mean>
                                <stddev>0.007</stddev>
                                <bias_mean>0.002</bias_mean>
                            </noise>
                        </y>
                        <z>
                            <noise type="gaussian">
                                <mean>0.0</mean>
                                <stddev>0.007</stddev>
                                <bias_mean>0.002</bias_mean>
                            </noise>
                        </z>
                    </linear_acceleration>
                </imu>
            </sensor>

            <!-- GPS Sensor -->
            <sensor name="robot_gps" type="gps">
                <update_rate>10</update_rate>
                <gps>
                    <position_sensing>
                        <horizontal>
                            <noise type="gaussian">
                                <mean>0.0</mean>
                                <stddev>2.5</stddev>
                            </noise>
                        </horizontal>
                        <vertical>
                            <noise type="gaussian">
                                <mean>0.0</mean>
                                <stddev>2.5</stddev>
                            </noise>
                        </vertical>
                    </position_sensing>
                    <velocity_sensing>
                        <horizontal>
                            <noise type="gaussian">
                                <mean>0.0</mean>
                                <stddev>0.1</stddev>
                            </noise>
                        </horizontal>
                    </velocity_sensing>
                </gps>
            </sensor>
        </link>

        <!-- Left Wheel -->
        <link name="left_wheel">
            <pose>0 0.4 -0.2 1.5707 0 0</pose>
            <inertial>
                <mass>5.0</mass>
                <inertia>
                    <ixx>0.1</ixx>
                    <iyy>0.1</iyy>
                    <izz>0.1</izz>
                </inertia>
            </inertial>
            <collision name="left_wheel_collision">
                <geometry>
                    <cylinder>
                        <radius>0.25</radius>
                        <length>0.1</length>
                    </cylinder>
                </geometry>
                <surface>
                    <friction>
                        <ode>
                            <mu>0.8</mu>
                            <mu2>0.8</mu2>
                        </ode>
                    </friction>
                </surface>
            </collision>
            <visual name="left_wheel_visual">
                <geometry>
                    <cylinder>
                        <radius>0.25</radius>
                        <length>0.1</length>
                    </cylinder>
                </geometry>
            </visual>
        </link>

        <!-- Right Wheel -->
        <link name="right_wheel">
            <pose>0 -0.4 -0.2 1.5707 0 0</pose>
            <inertial>
                <mass>5.0</mass>
                <inertia>
                    <ixx>0.1</ixx>
                    <iyy>0.1</iyy>
                    <izz>0.1</izz>
                </inertia>
            </inertial>
            <collision name="right_wheel_collision">
                <geometry>
                    <cylinder>
                        <radius>0.25</radius>
                        <length>0.1</length>
                    </cylinder>
                </geometry>
                <surface>
                    <friction>
                        <ode>
                            <mu>0.8</mu>
                            <mu2>0.8</mu2>
                        </ode>
                    </friction>
                </surface>
            </collision>
            <visual name="right_wheel_visual">
                <geometry>
                    <cylinder>
                        <radius>0.25</radius>
                        <length>0.1</length>
                    </cylinder>
                </geometry>
            </visual>
        </link>

        <!-- Wheel Joints -->
        <joint name="left_wheel_joint" type="revolute">
            <parent>base_link</parent>
            <child>left_wheel</child>
            <axis>
                <xyz>0 1 0</xyz>
                <limit>
                    <velocity>2.0</velocity>
                    <effort>40.0</effort>
                </limit>
            </axis>
        </joint>

        <joint name="right_wheel_joint" type="revolute">
            <parent>base_link</parent>
            <child>right_wheel</child>
            <axis>
                <xyz>0 1 0</xyz>
                <limit>
                    <velocity>2.0</velocity>
                    <effort>40.0</effort>
                </limit>
            </axis>
        </joint>

        <!-- Robot Controller Plugin -->
        <plugin name="ground_robot_controller" filename="librobotController.so">
            <update_rate>100</update_rate>
            <max_thrust>40.0</max_thrust>
            <max_torque>20.0</max_torque>
            <terrain_adaptation>
                <enabled>true</enabled>
                <response_rate>0.5</response_rate>
                <stability_margin>0.3</stability_margin>
            </terrain_adaptation>
            <safety_limits>
                <max_slope>30.0</max_slope>
                <min_clearance>0.1</min_clearance>
                <emergency_stop_decel>2.0</emergency_stop_decel>
            </safety_limits>
        </plugin>

        <!-- Sensor Suite Plugin -->
        <plugin name="sensor_suite" filename="libsensorPlugin.so">
            <camera_update_rate>30.0</camera_update_rate>
            <imu_update_rate>100.0</imu_update_rate>
            <gps_update_rate>10.0</gps_update_rate>
            <sensor_fusion>
                <enabled>true</enabled>
                <kalman_filter_params>
                    <process_noise>0.01</process_noise>
                    <measurement_noise>0.02</measurement_noise>
                </kalman_filter_params>
            </sensor_fusion>
        </plugin>
    </model>
</sdf>